Workbook

Sheet BPOP General Info
A1: Baseball Performance Optimization Program - BPOP
A3: Email | B3: mybaseballpop@gmail.com
A4: website | B4: www.baseballpop.com
A6: Full Name | B6: Baseball Performance Opimization Program
A7: Short Name | B7: Bpop
A9: Connections | B9: Github | D9: Baseballpop1213 | E9: !Norman12
B10: Repository | D10: Baseballpop_main
B12: Supabase Postgres Database Password | D12: Baseballpop's Org | E12: GlVn7hCe1jUowoxv
A16: Logos | B16: #VALUE! | C16: #VALUE! | D16: #VALUE! | E16: #VALUE! | F16: #VALUE!
B18: ,png | C18: .png | D18: .jpeg | E18: .png | F18: .svg
B20: Main | C20: Alternate | E20: Dark Background | F20: Vector

Sheet BPOP HS College Pro Eval (OLD)
A1: BPOP High School, College, and Pro assessment
K2: High School Ranges | S2: College Ranges | AA2: Pro Ranges
A3: Primary Category | B3: Secondary Category | C3: Test Name | E3: Description | F3: Selection Type | G3: Selection Optons | H3: Selection Details | I3: Value Range | K3: Red Range | L3: Yellow Range | M3: Green Range | N3: Bronze Threshold | O3: Silver Threshold | P3: Gold Threshold | Q3: Platinum Threshold | S3: Red Range | T3: Yellow Range | U3: Green Range | V3: Bronze Threshold | W3: Silver Threshold | X3: Gold Threshold | Y3: Platinum Threshold | AA3: Red Range | AB3: Yellow Range | AC3: Green Range | AD3: Bronze Threshold | AE3: Silver Threshold | AF3: Gold Threshold | AG3: Platinum Threshold
A5: Athletic Skills | B5: Speed | C5: Timed Run 1B (90ft) | E5: Have the player run from home plate straight through 1st base. | F5: INPUT with Optional Stopwatch | H5: Time - Seconds to the hundreth | I5: 2 Seconds - 10 Seconds | U5: 4.35 | AC5: 4.2
C6: Timed Run 4B (360ft) | E6: Have the player run from home plate around all four bases. | F6: INPUT with Optional Stopwatch | H6: Time - Seconds to the hundreth | I6: 10 Seconds - 60 Seconds
C7: 40 Yard Dash | E7: Have the player run 40 yards. | F7: INPUT with Optional Stopwatch | H7: Time - Seconds to the hundreth | I7: 3 Seconds - 12 Seconds | K7: >5.25 | L7: 4.9 - 5.25 | M7: <4.9 | N7: <=4.9 | O7: 4.7-4.89 | P7: 4.6-4.69 | Q7: <4.6 | S7: >4.95 | T7: 4.65-4.95 | U7: <4.65 | V7: <=4.65 | W7: 4.55-4.64 | X7: 4.45-4.54 | Y7: <4.45 | AA7: >4.65 | AB7: 4.5-4.65 | AC7: <4.5 | AD7: <4.5 | AE7: 4.42-4.49 | AF7: 4.30-4.41 | AG7: <4.3
B9: Strength | C9: Pull Ups | E9: Record the number of pull-ups the player can do in 60 seconds | F9: INPUT with 60 second countdown Timer | H9: Number | I9: 0 - 100
C10: Push Ups | E10: Record the number of push ups the player can do in 60 seconds | F10: INPUT with 60 second countdown Timer | H10: Number | I10: 0 - 100
C11: Sit Ups | E11: Record the number of sit-ups the player can do in 60 seconds | F11: INPUT with 60 second countdown Timer | H11: Number | I11: 0 - 200
B13: Power | C13: Seated Chest Pass | E13: Have the player sit on the edge of a chair or bench and hold a medicine ball with both hands against their chest. Have the player throw the medicine ball forward as far as possible. The player gets 3 attempts | F13: INPUT | G13: Separate Entry for each of the 3 attempts | H13: Feet and Inches | I13: 2ft - 40 ft
C14: Sit up and throw | E14: Have the player start in a hook-line position with a medicine ball above their head. Have the player site up and throw the medicine ball as far as possible.The player gets 3 attempts | F14: INPUT | G14: Separate Entry for each of the 3 attempts | H14: Feet and Inches | I14: 2ft - 40 ft
C15: Vertical Jump | E15: Measure the player's max vertical jump. The player can squat slightly to start, but cannot take a running start.The player gets 3 attempts | F15: INPUT | G15: Separate Entry for each of the 3 attempts | H15: Inches to the .25 of an inch | I15: 4 inches - 50 inches
B17: Balance | C17: SLS Eyes Open | E17: Have the player get into a single leg stance with their thigh parallel to the ground and the arms by their side. Once stable, have them hold this position for as long as possible up to 30 seconds. | F17: INPUT with Stopwatch that automatically stops at 30 seconds. The user can click a stop button to record the time. | G17: Separate Entry for Right and Left Side | H17: Time - Seconds to the hundreth | I17: 0 Seconds - 30 Seconds
C18: SLS Eyes Closed | E18: Have the player get into a single leg stance with their thigh parallel to the ground and the arms by their side. Once stable, have the player close their eyes and hold this position for as long as possible up to 30 seconds. | F18: INPUT with Stopwatch that automatically stops at 30 seconds. The user can click a stop button to record the time. | G18: Separate Entry for Right and Left Side | H18: Time - Seconds to the hundreth | I18: 0 Seconds - 30 Seconds
B20: Mobility | C20: MSR | E20: Have the player stand straight, feet together, with a bat across the shoulders. Then have them rotate their body around to look behind. The player should be able to rotate their torso more than 180 degrees. | F20: SELECT - Less than 180 Degrees, Equal to 180 Degrees, Greater than 180 Degress | G20: Separate Selection for Right and Left Side | H20: Select only 1 option | I20: No Range - Specific Options
C21: Toe Touch | E21: Have the player stand tall with hte feet together. Have them try to touch their toes without bending the knees. If they can touch their toes, have them try to touch the ground in front of their toes. | F21: SELECT - Cannot Touch Toes, Touches Toes, Touches Ground | H21: Select only 1 option | I21: No Range - Specific Options
C22: Deep Squat | E22: Have the player stand with their feet shoulder width apart with the arms striaght above their head. Have them do a deep squat trying to get their pelvis below the knees without the arms moving forward or the ankles flaring. | F22: SELECT - Full Overhead Deep Squat, Arms Move Forward, Pelvis not below the knees, Ankles Flare | G22: Full Overhead Deep Squat, Arms move forward of head, Pelvis not below the hips, Ankles Flare | H22: Select 1 or Multiple Options - If "Full Overhead Deep Squat" is selected, then the other options become unavailable. If not, then the user could select one or more of the remaining options. | I22: No Range - Specific Options
A24: Hitting | B24: Contact | C24: Tee Line Drive Test | E24: Have the player attempt to hit line drives off a tee. Count how many the player can hit in a row with a maximum of 10. | F24: INPUT | H24: Number | I24: 0 - 10
B25: Power | C25: Max Exit Velo Tee | E25: The player gets 3 attempts to max out their exit velow off a tee. | F25: INPUT - Exit Velo | G25: Separate Input for each of the 3 attempts | H25: MPH | I25: 0 MPH - 140 MPH
B26: Contact and Power | C26: 10 Swing Fastball Matrix | E26: With live pitching or a machine, have the player take 10 swings on fastballs. The player can choose the 10 pitches. If the player swings and misses, they get 0 points. If the player hits a foul ball, foul tip, or weak infield ball, they get 1 point. If the player hits a ball that would roll past the infielders or a fly ball that could be caught by an infielder, they get 2 points. If the player hits a hard grounder or fly ball, they get 3 points. Balls that fly over the outfielders or hard gap/line hits will get 4 points. The player can get 5 points for a no-doubt home run. | F26: SELECT Miss, Foul, Weak Infield, Ground Ball, Hard Ground Ball, Fly Ball, Hard Gap or Line, Home Run, INPUT Exit Velo | G26: Separate Entry for each of the 10 Swings | H26: Selection and MPH | I26: 0 Points - 50 Points
B27: Contact and Power | C27: 5 Swing Curves | E27: With live pitching or a machine, have the player take 5 swings on Curves. The player can choose the 5 pitches. If the player swings and misses, they get 0 points. If the player hits a foul ball, foul tip, or weak infield ball, they get 1 point. If the player hits a ball that would roll past the infielders or a fly ball that could be caught by an infielder, they get 2 points. If the player hits a hard grounder or fly ball, they get 3 points. Balls that fly over the outfielders or hard gap/line hits will get 4 points. The player can get 5 points for a no-doubt home run. | F27: SELECT Miss, Foul, Weak Infield, Ground Ball, Hard Ground Ball, Fly Ball, Hard Gap or Line, Home Run, INPUT Exit Velo | G27: Separate Entry for each of the 5 Swings | H27: Selection and MPH | I27: 0 Points - 25 Points
B28: Contact and Power | C28: 5 Swing Varied Speed | E28: With live pitching or a machine, have the player take 5 swings on off-speed pitches. The player can choose the 5 pitches. Pitches in this test should vary from a full speed fastball to a very slow change-up. If the player swings and misses, they get 0 points. If the player hits a foul ball, foul tip, or weak infield ball, they get 1 point. If the player hits a ball that would roll past the infielders or a fly ball that could be caught by an infielder, they get 2 points. If the player hits a hard grounder or fly ball, they get 3 points. Balls that fly over the outfielders or hard gap/line hits will get 4 points. The player can get 5 points for a no-doubt home run. | F28: SELECT Miss, Foul, Weak Infield, Ground Ball, Hard Ground Ball, Fly Ball, Hard Gap or Line, Home Run, INPUT Exit Velo | G28: Separate Entry for each of the 5 Swings | H28: Selection and MPH | I28: 0 Points - 25 Points
B29: Power | C29: Max Bat Speed | E29: Have the player make dry swings with their game bat in front of a radar and measure the maximum bat speed. The player gets 3 attempts. | F29: INPUT | G29: Separate Input for each of the 3 attempts | H29: MPH | I29: 0 MPH - 120 MPH
A31: Position Specific | B31: Pitcher | C31: Max Pitch Velo | E31: Have the player throw 5 pitches from 60 feet 6 inches, trying to max out their Velocity. | F31: INPUT | G31: Separate Input for each of the 5 attempts | H31: MPH | I31: 0 MPH - 120 MPH
B32: Pitcher | C32: 10 Fastball Test | E32: Have the player pitch toward a 9-slot pitching target from 60 feet 6 inches. Before each pitch, the player should "call his shot" for the specific slot he is aiming at. The player gets 0 points if they miss the target, 1 point if they hit the target, but not in the chosen slot, and 3 points for hitting the called section of the target. | F32: SELECT Missed Target, Hit General Target, Hit Specific Section, INPUT Velocity | G32: Separate Entry for each of the 10 pitches | H32: Selection and MPH | I32: 0 Points - 30 Points, 0 MPH - 120 MPH
B33: Pitcher | C33: 5 Pitch Additional Pitch (from intake) | E33: Have the player pitch toward a 9-slot pitching target from 60 feet 6 inches. Before each pitch, the player should "call his shot" for the specific slot he is aiming at. The player gets 0 points if they miss the target, 1 point if they hit the target, but not in the chosen slot, and 3 points for hitting the called section of the target. | F33: SELECT Missed Target, Hit General Target, Hit Specific Section | G33: Separate Entry for each of the 5 pitches | H33: Selection | I33: 0 Points - 15 Points
B34: Pitcher | C34: 5 Pitch Additional Pitch (from intake) | E34: Have the player pitch toward a 9-slot pitching target from 60 feet 6 inches. Before each pitch, the player should "call his shot" for the specific slot he is aiming at. The player gets 0 points if they miss the target, 1 point if they hit the target, but not in the chosen slot, and 3 points for hitting the called section of the target. | F34: SELECT Missed Target, Hit General Target, Hit Specific Section, INPUT Velocity | G34: Separate Entry for each of the 5 pitches | H34: Selection and MPH | I34: 0 Points - 15 Points, 0 MPH - 120 MPH
B35: Pitcher | C35: 5 Pitch Additional Pitch (from intake) | E35: Have the player pitch toward a 9-slot pitching target from 60 feet 6 inches. Before each pitch, the player should "call his shot" for the specific slot he is aiming at. The player gets 0 points if they miss the target, 1 point if they hit the target, but not in the chosen slot, and 3 points for hitting the called section of the target. | F35: SELECT Missed Target, Hit General Target, Hit Specific Section, INPUT Velocity | G35: Separate Entry for each of the 5 pitches | H35: Selection and MPH | I35: 0 Points - 15 Points, 0 MPH - 120 MPH
B37: Catcher | C37: 20 Pitch Screen | E37: Have the catcher set up to catch a live pitcher or machine. Have the player catch 20 pitches. 10 pitches should be pretty standard strikes in the zone. 5 should be balls outside the zone, and 5 should be in the dirt in front of the player. The player gets 0 points for a passed ball, 1 point for a blocked ball that stays in front of them, and 2 points for a catch or scoop. | F37: SELECT Pitch Type - In the Zone, Outside the Zone, In the Dirt, SELECT Passed Ball, Blocked Ball, Catch, Scoop | G37: Separate Entry for each of the 20 pitches | H37: Multiple Selections | I37: 0 Points - 40 Points
B38: Catcher | C38: Timed throw to 2B | E38: Have the catcher receive a pitch a then throw it to second base. There can be a target or player at second base. Time the player from the time the ball crosses the plate to the time the ball reaches second base. | F38: INPUT with optional stopwatch | H38: Time - Seconds to the hundreth | I38: .5 seconds - 6 seconds
B39: Catcher | C39: Target Throw 2B | E39: Have the catcher receive 5 pitches and then throw it to 2B. The player gets one point for catching the ball and making a throw, and 3 points for hitting the target. | F39: SELECT No Catch, Throw Missed Target, Throw Hit Target | G39: Separate Entry for each of the 5 pitches | H39: Selection | I39: 0 Points - 15 Points
B41: First Base | C41: 10 Catch 1B | E41: Have the player set up at first base to take throws from ShortStop. Have a machine or player throw 10 balls at the player. 5 should be good throws and 5 should be high, low, or to the sides of the player. The player gets 0 points for a missed catch that gets by, 1 point for a blocked ball , and 3 points for a catch with the foot on the bag. | F41: SELECT Throw Type - Good or Hard, INPUT Miss, Blocked, or Catch | G41: Separate Entry for each of the 10 throws | H41: Multiple Selections | I41: 0 Points - 30 Points
B42: First Base | C42: Scoops Test | E42: Have a machine or player stand 40ft from first base. Throw 10 balls short of the player that the first baseman must scoop. The player gets 0 points for a missed catch that gets by, 1 point for a blocked ball, and 3 points for a scoop with the foot on the bag. | F42: SELECT Miss, Blocked Ball, Catch | G42: Separate Entry for each of the 10 throws | H42: Selection | I42: 0 Points - 30 Points
B43: First Base | C43: First Base R/L/C Grounders | E43: Hit a total of 6 ground balls to the player at first base. 2 will be to the center, 2 will make the player move at least 10 feet to the right, and 2 will make the player move at least 10 feet to the left. The player will get 0 points if they fail to field the ground ball, and 2 points if they field the ball and run to touch first base. | F43: SELECT - Right, Center, Left, SELECT - Didn't Field, Fielded but Missed Target, Fielded and Hit Target | G43: Separate Entry for each of the 6 grounders | H43: Multiple Selections | I43: 0 Points - 12 Points
B44: First Base | C44: Flys | E44: Hit 3 fly balls to the first base side. These can be into foul territory, behind the player or in front of the player. The player gets 2 points for each catch and 0 for each miss. | F44: SELECT - Miss, Catch | G44: Separate Entry for each of the 3 fly balls | H44: Selection | I44: 0 Points - 6 Points
B45: First Base | C45: Line Drives | E45: Hit 3 line drives to the player at first base. The player gets 2 points for a catch and 0 for a miss. | F45: SELECT - Miss, Catch | G45: Separate Entry for each of the 3 Line Drives | H45: Selection | I45: 0 Points - 6 Points
B47: Middle Infield (2B, SS, 3B) | C47: R/L/C Grounders 2B | E47: Hit 6 ground balls to the player at 2B. 2 should be at the player, 2 should make the player move at least 10ft to the right, and 2 should make the player move at least 10ft to the left. The player should not know what direction is coming. The player gets 1 point for fielding the ball cleanly and 2 points if they field it cleanly and hit the target at first base. | F47: SELECT - Right, Center, Left, SELECT - Didn't Field, Fielded but Missed Target, Fielded and Hit Target | G47: Separate Entry for each of the 6 grounders | H47: Multiple Selections | I47: 0 Points - 12 Points
C48: R/L/C Grounders SS | E48: Hit 6 ground balls to the player at SS. 2 should be at the player, 2 should make the player move at least 10ft to the right, and 2 should make the player move at least 10ft to the left. The player should not know what direction is coming. The player gets 1 point for fielding the ball cleanly and 2 points if they field it cleanly and hit the target at first base. | F48: SELECT - Right, Center, Left, SELECT - Didn't Field, Fielded but Missed Target, Fielded and Hit Target | G48: Separate Entry for each of the 6 grounders | H48: Multiple Selections | I48: 0 Points - 12 Points
C49: R/L/C Grounders 3B | E49: Hit 6 ground balls to the player at 3B. 2 should be at the player, 2 should make the player move at least 10ft to the right, and 2 should make the player move at least 10ft to the left. The player should not know what direction is coming. The player gets 1 point for fielding the ball cleanly and 2 points if they field it cleanly and hit the target at first base. | F49: SELECT - Right, Center, Left, SELECT - Didn't Field, Fielded but Missed Target, Fielded and Hit Target | G49: Separate Entry for each of the 6 grounders | H49: Multiple Selections | I49: 0 Points - 12 Points
B50: Middle Infield (2B, SS, 3B) | C50: Infield Fly 2B | E50: Hit 3 fly balls to the player at 2B. These should be within a 20ft radius around the player. The player gets 0 points for a miss and 2 points for a catch. | F50: SELECT - Miss, Catch | G50: Separate Entry for each of the 3 fly balls | H50: Selection | I50: 0 Points - 6 Points
...

Sheet BPOP 12U-14U Eval (OLD)
A1: BPOP 14U-12U Assessment
K2: 12U Ranges | S2: 13U Ranges | AA2: 14U Ranges
A3: Primary Category | B3: Secondary Category | C3: Test Name | E3: Description | F3: Selection Type | G3: Selection Optons | H3: Selection Details | I3: Value Range | K3: Red Range | L3: Yellow Range | M3: Green Range | N3: Bronze Threshold | O3: Silver Threshold | P3: Gold Threshold | Q3: Platinum Threshold | S3: Red Range | T3: Yellow Range | U3: Green Range | V3: Bronze Threshold | W3: Silver Threshold | X3: Gold Threshold | Y3: Platinum Threshold | AA3: Red Range | AB3: Yellow Range | AC3: Green Range | AD3: Bronze Threshold | AE3: Silver Threshold | AF3: Gold Threshold | AG3: Platinum Threshold
A5: Athletic Skills | B5: Speed | C5: Timed Run 1B (90ft) | E5: Have the player run from home plate straight through 1st base. | F5: INPUT with Optional Stopwatch | H5: Time - Seconds to the hundreth | I5: 2 Seconds - 10 Seconds | U5: 4.35 | AC5: 4.2
C6: Timed Run 4B (360ft) | E6: Have the player run from home plate around all four bases. | F6: INPUT with Optional Stopwatch | H6: Time - Seconds to the hundreth | I6: 10 Seconds - 60 Seconds
B8: Strength | C8: Push Ups | E8: Record the number of push ups the player can do in 30 seconds | F8: INPUT with 30 second countdown Timer | H8: Number | I8: 0 - 50
C9: Sit Ups | E9: Record the number of sit-ups the player can do in 30 seconds | F9: INPUT with 30 second countdown Timer | H9: Number | I9: 0 - 50
B10: Power | C10: Vertical Jump | E10: Measure the player's max vertical jump. The player can squat slightly to start, but cannot take a running start.The player gets 3 attempts | F10: INPUT | G10: Separate Entry for each of the 3 attempts | H10: Inches to the .25 of an inch | I10: 4 inches - 50 inches
B11: Balance | C11: SLS Eyes Open | E11: Have the player get into a single leg stance with their thigh parallel to the ground and the arms by their side. Once stable, have them hold this position for as long as possible up to 30 seconds. | F11: INPUT with Stopwatch that automatically stops at 30 seconds. The user can click a stop button to record the time. | G11: Separate Entry for Right and Left Side | H11: Time - Seconds to the hundreth | I11: 0 Seconds - 30 Seconds
C12: SLS Eyes Closed | E12: Have the player get into a single leg stance with their thigh parallel to the ground and the arms by their side. Once stable, have the player close their eyes and hold this position for as long as possible up to 30 seconds. | F12: INPUT with Stopwatch that automatically stops at 30 seconds. The user can click a stop button to record the time. | G12: Separate Entry for Right and Left Side | H12: Time - Seconds to the hundreth | I12: 0 Seconds - 30 Seconds
B14: Mobility | C14: MSR | E14: Have the player stand straight, feet together, with a bat across the shoulders. Then have them rotate their body around to look behind. The player should be able to rotate their torso more than 180 degrees. | F14: SELECT - Less than 180 Degrees, Equal to 180 Degrees, Greater than 180 Degress | G14: Separate Selection for Right and Left Side | H14: Select only 1 option | I14: No Range - Specific Options
C15: Toe Touch | E15: Have the player stand tall with hte feet together. Have them try to touch their toes without bending the knees. If they can touch their toes, have them try to touch the ground in front of their toes. | F15: SELECT - Cannot Touch Toes, Touches Toes, Touches Ground | H15: Select only 1 option | I15: No Range - Specific Options
C16: Deep Squat | E16: Have the player stand with their feet shoulder width apart with the arms striaght above their head. Have them do a deep squat trying to get their pelvis below the knees without the arms moving forward or the ankles flaring. | F16: SELECT - Full Overhead Deep Squat, Arms Move Forward, Pelvis not below the knees, Ankles Flare | G16: Full Overhead Deep Squat, Arms move forward of head, Pelvis not below the hips, Ankles Flare | H16: Select 1 or Multiple Options - If "Full Overhead Deep Squat" is selected, then the other options become unavailable. If not, then the user could select one or more of the remaining options. | I16: No Range - Specific Options
A18: Hitting | C18: Tee Line Drive Test | E18: Have the player attempt to hit line drives off a tee. Count how many the player can hit in a row with a maximum of 10. | F18: INPUT | H18: Number | I18: 0 - 10
C19: Max Exit Velo Tee | E19: The player gets 3 attempts to max out their exit velow off a tee. | F19: INPUT - Exit Velo | G19: Separate Input for each of the 3 attempts | H19: MPH | I19: 0 MPH - 140 MPH
C20: 10 Swing Fastball Matrix | E20: With live pitching or a machine, have the player take 10 swings on fastballs. The player can choose the 10 pitches. If the player swings and misses, they get 0 points. If the player hits a foul ball, foul tip, or weak infield ball, they get 1 point. If the player hits a ball that would roll past the infielders or a fly ball that could be caught by an infielder, they get 2 points. If the player hits a hard grounder or fly ball, they get 3 points. Balls that fly over the outfielders or hard gap/line hits will get 4 points. The player can get 5 points for a no-doubt home run. | F20: SELECT Miss, Foul, Weak Infield, Ground Ball, Hard Ground Ball, Fly Ball, Hard Gap or Line, Home Run, INPUT Exit Velo | G20: Separate Entry for each of the 10 Swings | H20: Selection and MPH | I20: 0 Points - 50 Points
C21: 5 Swing Varied Speed | E21: With live pitching or a machine, have the player take 5 swings on off-speed pitches. The player can choose the 5 pitches. Pitches in this test should vary from a full speed fastball to a very slow change-up. If the player swings and misses, they get 0 points. If the player hits a foul ball, foul tip, or weak infield ball, they get 1 point. If the player hits a ball that would roll past the infielders or a fly ball that could be caught by an infielder, they get 2 points. If the player hits a hard grounder or fly ball, they get 3 points. Balls that fly over the outfielders or hard gap/line hits will get 4 points. The player can get 5 points for a no-doubt home run. | F21: SELECT Miss, Foul, Weak Infield, Ground Ball, Hard Ground Ball, Fly Ball, Hard Gap or Line, Home Run, INPUT Exit Velo | G21: Separate Entry for each of the 5 Swings | H21: Selection and MPH | I21: 0 Points - 25 Points
C22: Max Bat Speed | E22: Have the player make dry swings with their game bat in front of a radar and measure the maximum bat speed. The player gets 3 attempts. | F22: INPUT | G22: Separate Input for each of the 3 attempts | H22: MPH | I22: 0 MPH - 120 MPH
A24: Position Specific | B24: Pitcher | C24: Max Pitch Velo | E24: Have the player throw 5 pitches from 60 feet 6 inches, trying to max out their Velocity. | F24: INPUT | G24: Separate Input for each of the 5 attempts | H24: MPH | I24: 0 MPH - 120 MPH
B25: Pitcher | C25: 10 Fastball Test | E25: Have the player pitch toward a 9-slot pitching target from 60 feet 6 inches. Before each pitch, the player should "call his shot" for the specific slot he is aiming at. The player gets 0 points if they miss the target, 1 point if they hit the target, but not in the chosen slot, and 3 points for hitting the called section of the target. | F25: SELECT Missed Target, Hit General Target, Hit Specific Section, INPUT Velocity | G25: Separate Entry for each of the 10 pitches | H25: Selection and MPH | I25: 0 Points - 30 Points, 0 MPH - 120 MPH
B27: Catcher | C27: 10 Pitch Screen | E27: Have the catcher set up to catch a live pitcher or machine. Have the player catch 10 pitches. 6 pitches should be pretty standard strikes in the zone. 2 should be balls outside the zone, and 2 should be in the dirt in front of the player. The player gets 0 points for a passed ball, 1 point for a blocked ball that stays in front of them, and 2 points for a catch or scoop. | F27: SELECT Pitch Type - In the Zone, Outside the Zone, In the Dirt, SELECT Passed Ball, Blocked Ball, Catch, Scoop | G27: Separate Entry for each of the 10 pitches | H27: Multiple Selections | I27: 0 Points - 20 Points
B28: Catcher | C28: Timed throw to 2B | E28: Have the catcher receive a pitch a then throw it to second base. There can be a target or player at second base. Time the player from the time the ball crosses the plate to the time the ball reaches second base. | F28: INPUT with optional stopwatch | H28: Time - Seconds to the hundreth | I28: .5 seconds - 10 seconds
B29: Catcher | C29: Target Throw 2B | E29: Have the catcher receive 5 pitches and then throw it to 2B. The player gets one point for catching the ball and making a throw, and 3 points for hitting the target. | F29: SELECT No Catch, Throw Missed Target, Throw Hit Target | G29: Separate Entry for each of the 5 pitches | H29: Selection | I29: 0 Points - 15 Points
B31: First Base | C31: 10 Catch 1B | E31: Have the player set up at first base to take throws from ShortStop. Have a machine or player throw 10 balls at the player. 5 should be good throws and 5 should be high, low, or to the sides of the player. The player gets 0 points for a missed catch that gets by, 1 point for a blocked ball , and 3 points for a catch with the foot on the bag. | F31: SELECT Throw Type - Good or Hard, INPUT Miss, Blocked, or Catch | G31: Separate Entry for each of the 10 throws | H31: Multiple Selections | I31: 0 Points - 30 Points
B32: First Base | C32: Scoops Test | E32: Have a machine or player stand 40ft from first base. Throw 5 balls short of the player that the first baseman must scoop. The player gets 0 points for a missed catch that gets by, 1 point for a blocked ball, and 3 points for a scoop with the foot on the bag. | F32: SELECT Miss, Blocked Ball, Catch | G32: Separate Entry for each of the 5 throws | H32: Selection | I32: 0 Points - 15 Points
B33: First Base | C33: First Base R/L/C Grounders | E33: Hit a total of 6 ground balls to the player at first base. 2 will be to the center, 2 will make the player move at least 10 feet to the right, and 2 will make the player move at least 10 feet to the left. The player will get 0 points if they fail to field the ground ball, and 2 points if they field the ball and run to touch first base. | F33: SELECT - Right, Center, Left, SELECT - Didn't Field, Fielded but Missed Target, Fielded and Hit Target | G33: Separate Entry for each of the 6 grounders | H33: Multiple Selections | I33: 0 Points - 12 Points
B34: First Base | C34: Flys | E34: Hit 3 fly balls to the first base side. These can be into foul territory, behind the player or in front of the player. The player gets 2 points for each catch and 0 for each miss. | F34: SELECT - Miss, Catch | G34: Separate Entry for each of the 3 fly balls | H34: Selection | I34: 0 Points - 6 Points
B35: First Base | C35: Line Drives | E35: Hit 3 line drives to the player at first base. The player gets 2 points for a catch and 0 for a miss. | F35: SELECT - Miss, Catch | G35: Separate Entry for each of the 3 Line Drives | H35: Selection | I35: 0 Points - 6 Points
B37: Middle Infield (2B, SS, 3B) | C37: R/L/C Grounders 2B | E37: Hit 6 ground balls to the player at 2B. 2 should be at the player, 2 should make the player move at least 10ft to the right, and 2 should make the player move at least 10ft to the left. The player should not know what direction is coming. The player gets 1 point for fielding the ball cleanly and 2 points if they field it cleanly and hit the target at first base. | F37: SELECT - Right, Center, Left, SELECT - Didn't Field, Fielded but Missed Target, Fielded and Hit Target | G37: Separate Entry for each of the 6 grounders | H37: Multiple Selections | I37: 0 Points - 12 Points
C38: R/L/C Grounders SS | E38: Hit 6 ground balls to the player at SS. 2 should be at the player, 2 should make the player move at least 10ft to the right, and 2 should make the player move at least 10ft to the left. The player should not know what direction is coming. The player gets 1 point for fielding the ball cleanly and 2 points if they field it cleanly and hit the target at first base. | F38: SELECT - Right, Center, Left, SELECT - Didn't Field, Fielded but Missed Target, Fielded and Hit Target | G38: Separate Entry for each of the 6 grounders | H38: Multiple Selections | I38: 0 Points - 12 Points
C39: R/L/C Grounders 3B | E39: Hit 6 ground balls to the player at 3B. 2 should be at the player, 2 should make the player move at least 10ft to the right, and 2 should make the player move at least 10ft to the left. The player should not know what direction is coming. The player gets 1 point for fielding the ball cleanly and 2 points if they field it cleanly and hit the target at first base. | F39: SELECT - Right, Center, Left, SELECT - Didn't Field, Fielded but Missed Target, Fielded and Hit Target | G39: Separate Entry for each of the 6 grounders | H39: Multiple Selections | I39: 0 Points - 12 Points
B40: Middle Infield (2B, SS, 3B) | C40: Infield Fly 2B | E40: Hit 3 fly balls to the player at 2B. These should be within a 20ft radius around the player. The player gets 0 points for a miss and 2 points for a catch. | F40: SELECT - Miss, Catch | G40: Separate Entry for each of the 3 fly balls | H40: Selection | I40: 0 Points - 6 Points
C41: Infield Fly SS | E41: Hit 3 fly balls to the player at SS. These should be within a 20ft radius around the player. The player gets 0 points for a miss and 2 points for a catch. | F41: SELECT - Miss, Catch | G41: Separate Entry for each of the 3 fly balls | H41: Selection | I41: 0 Points - 6 Points
C42: Infield Fly 3B | E42: Hit 3 fly balls to the player at 3B. These should be within a 20ft radius around the player. The player gets 0 points for a miss and 2 points for a catch. | F42: SELECT - Miss, Catch | G42: Separate Entry for each of the 3 fly balls | H42: Selection | I42: 0 Points - 6 Points
B43: Middle Infield (2B, SS, 3B) | C43: Line Drives 2B | E43: Hit 3 Line Drives to the player at 2B. These should make the player move inside a 10ft radius. The player gets 0 points for a miss and 2 points for a catch. | F43: SELECT - Miss, Catch | G43: Separate Entry for each of the 3 Line Drives | H43: Selection | I43: 0 Points - 6 Points
C44: Line Drives SS | E44: Hit 3 Line Drives to the player at SS. These should make the player move inside a 10ft radius. The player gets 0 points for a miss and 2 points for a catch. | F44: SELECT - Miss, Catch | G44: Separate Entry for each of the 3 Line Drives | H44: Selection | I44: 0 Points - 6 Points
C45: Line Drives 3B | E45: Hit 3 Line Drives to the player at 3B. These should make the player move inside a 10ft radius. The player gets 0 points for a miss and 2 points for a catch. | F45: SELECT - Miss, Catch | G45: Separate Entry for each of the 3 Line Drives | H45: Selection | I45: 0 Points - 6 Points
B46: Middle Infield (2B, SS, 3B) | C46: SS to First Time | E46: Hit a ball or use a machine to send a ball to a player at shortstop. The ball should be approximately 50 MPH. Time the player from the moment the balll leaves the bat to the time the ball reaches First Base. | F46: INPUT with Optional Stopwatch | H46: Time - Seconds to the hundreth | I46: .5 seconds - 8 seconds
B50: Outfield | C50: 20 X 20 Matrix | E50: Set up a 20 yard radius around the player. Hit 10 fly balls to the player at varied points around the coverage area from 60 yards. The player gets 2 points for each catch and 0 for each miss. | F50: SELECT - Miss, Catch | G50: Separate Entry for each of the 10 fly balls | H50: Selection | I50: 0 Points - 20 Points
B51: Outfield | C51: 100 ft throw to target | E51: Set up a pitching target at 100ft from the player. Have the player make 5 throws at the target. The player can get a running start as long as they don't move in front of the 120ft marker. The player gets 0 points for a throw that comes up more than 10 ft short of the target, 1 point for a throw that lands between 10ft and the target, 2 points for a throw that lands at or past the target but misses, and 4 points for each throw that hits the target. | F51: SELECT - >10ft Short, Lands short but misses the target, Bounces into the Target, Lands at or Past the Target, Hits the Target | G51: Separate Entry for each of the 5 throws | H51: Selection | I51: 0 Points - 20 Points
...

Sheet BPOP HS COLL PRO Eval
A1: #VALUE! | C1: BPOP High School, College, and Pro Evals
K2: High School Ranges | AE2: College Ranges | AY2: Pro Ranges
A3: Primary Category | B3: Secondary Category | C3: Test Name | D3: Score Definition | E3: Description | F3: Selection Type | G3: Selection Optons | H3: Selection Details | I3: Value Range | K3: Red Range | L3: Yellow Range | M3: Green Range | N3: Bronze Threshold | O3: Silver Threshold | P3: Gold Threshold | Q3: Platinum Threshold | R3: Total Point Cacluation | S3: Sample Data RED | T3: Sample Calc RED | U3: Sample Data GREEN | V3: Sample Calc GREEN | W3: Max Score | X3: Normalized Max | Y3: Normalized Sample Calc RED | Z3: Normalized Sample Calc GREEN | AA3: Silver Calc | AB3: Gold Calc | AC3: Platinum Calc | AE3: Red Range | AF3: Yellow Range | AG3: Green Range | AH3: Bronze Threshold | AI3: Silver Threshold | AJ3: Gold Threshold | AK3: Platinum Threshold | AL3: Total Point Cacluation | AM3: Sample Data RED | AN3: Sample Calc RED | AO3: Sample Data GREEN | AP3: Sample Calc GREEN | AQ3: Max Score | AR3: Normalized Max | AS3: Normalized Sample Calc RED | AT3: Normalized Sample Calc GREEN | AU3: Silver Calc | AV3: Gold Calc | AW3: Platinum Calc | AY3: Red Range | AZ3: Yellow Range | BA3: Green Range | BB3: Bronze Threshold | BC3: Silver Threshold | BD3: Gold Threshold | BE3: Platinum Threshold | BF3: Total Point Cacluation | BG3: Sample Data RED | BH3: Sample Calc RED | BI3: Sample Data GREEN | BJ3: Sample Calc GREEN | BK3: Max Score | BL3: Normalized Max | BM3: Normalized Sample Calc RED | BN3: Normalized Sample Calc GREEN | BO3: Silver Calc | BP3: Gold Calc | BQ3: Platinum Calc
A5: Athletic Skills | B5: Speed | C5: Timed Run 1B | D5: 1BSPEED | E5: Have the player run from home plate straight through 1st base. | F5: INPUT BASE LENGTH, INPUT with Optional Stopwatch | G5: NOTE - Data will be stored as Feet Per Second (base length / Time) | H5: FEET, Time - Seconds to the hundreth | I5: 40 - 90 FT, 2 Seconds - 10 Seconds | K5: 4.5 | L5: BETWEEN | M5: 4.15 | N5: 4.15 | O5: 4.05 | P5: 3.9 | Q5: 3.75 | R5: (1BSPEEDFPS-7FPS)*3 | S5: =K6 -> 20 | T5: =(S5-7)*3 -> 39 | U5: =M6 -> 21.686747 | V5: =(U5-7)*3 -> 44.060241 | W5: 60 | AA5: =(O6-7)*3 -> 45.666667 | AB5: =(P6-7)*3 -> 48.230769 | AC5: =(Q6-7)*3 -> 51 | AE5: 4.26 | AF5: BETWEEN | AG5: 3.95 | AH5: 3.95 | AI5: 3.85 | AJ5: 3.75 | AK5: 3.55 | AL5: (1BSPEEDFPS-7FPS)*3 | AM5: =AE6 -> 21.126761 | AN5: =(AM5-7)*3 -> 42.380282 | AO5: =AG6 -> 22.78481 | AP5: =(AO5-7)*3 -> 47.35443 | AQ5: 60 | AU5: =(AI6-7)*3 -> 49.12987 | AV5: =(AJ6-7)*3 -> 51 | AW5: =(AK6-7)*3 -> 55.056338 | AY5: 3.76 | AZ5: BETWEEN | BA5: 3.55 | BB5: 3.55 | BC5: 3.5 | BD5: 3.4 | BE5: 3.15 | BF5: (1BSPEEDFPS-7FPS)*3 | BG5: =AY6 -> 23.93617 | BH5: =(BG5-7)*3 -> 50.808511 | BI5: =BA6 -> 25.352113 | BJ5: =(BI5-7)*3 -> 55.056338 | BK5: 70 | BO5: =(BC6-7)*3 -> 56.142857 | BP5: =(BD6-7)*3 -> 58.411765 | BQ5: =(BE6-7)*3 -> 64.714286
J6: FT/SEC | K6: =$K$9/K5 -> 20 | L6: BETWEEN | M6: =$K$9/M5 -> 21.686747 | N6: =$K$9/N5 -> 21.686747 | O6: =$K$9/O5 -> 22.222222 | P6: =$K$9/P5 -> 23.076923 | Q6: =$K$9/Q5 -> 24 | AD6: FT/SEC | AE6: =$AE$9/AE5 -> 21.126761 | AF6: BETWEEN | AG6: =$AE$9/AG5 -> 22.78481 | AH6: =$AE$9/AH5 -> 22.78481 | AI6: =$AE$9/AI5 -> 23.376623 | AJ6: =$AE$9/AJ5 -> 24 | AK6: =$AE$9/AK5 -> 25.352113 | AX6: FT/SEC | AY6: =$AY$9/AY5 -> 23.93617 | AZ6: BETWEEN | BA6: =$AY$9/BA5 -> 25.352113 | BB6: =$AY$9/BB5 -> 25.352113 | BC6: =$AY$9/BC5 -> 25.714286 | BD6: =$AY$9/BD5 -> 26.470588 | BE6: =$AY$9/BE5 -> 28.571429
C7: Timed Run 4B | D7: 4BSPEED | E7: Have the player run from home plate around all four bases. | F7: INPUT BASE LENGTH, INPUT with Optional Stopwatch | G7: NOTE - Data will be stored as Feet Per Second (base length / Time) | H7: FEET, Time - Seconds to the hundreth | I7: 40 - 90 FT, 2 Seconds - 30 Seconds | K7: 18 | L7: BETWEEN | M7: 16.5 | N7: 16.5 | O7: 15.75 | P7: 15 | Q7: 14.25 | R7: (4BSPEEDFPS-7FPS)*3 | S7: =K8 -> 20 | T7: =(S7-7)*3 -> 39 | U7: =M8 -> 21.818182 | V7: =(U7-7)*3 -> 44.454545 | W7: 65 | AA7: =(O8-7)*3 -> 47.571429 | AB7: =(P8-7)*3 -> 51 | AC7: =(Q8-7)*3 -> 54.789474 | AE7: 17 | AF7: BETWEEN | AG7: 15 | AH7: 15 | AI7: 14.5 | AJ7: 13.75 | AK7: 13 | AL7: (4BSPEEDFPS-7FPS)*3 | AM7: =AE8 -> 21.176471 | AN7: =(AM7-7)*3 -> 42.529412 | AO7: =AG8 -> 24 | AP7: =(AO7-7)*3 -> 51 | AQ7: 65 | AU7: =(AI8-7)*3 -> 53.482759 | AV7: =(AJ8-7)*3 -> 57.545455 | AW7: =(AK8-7)*3 -> 62.076923 | AY7: 16 | AZ7: BETWEEN | BA7: 14.5 | BB7: 14.5 | BC7: 14 | BD7: 13 | BE7: 12 | BF7: (4BSPEEDFPS-7FPS)*3 | BG7: =AY8 -> 22.5 | BH7: =(BG7-7)*3 -> 46.5 | BI7: =BA8 -> 24.827586 | BJ7: =(BI7-7)*3 -> 53.482759 | BK7: 75 | BO7: =(BC8-7)*3 -> 56.142857 | BP7: =(BD8-7)*3 -> 62.076923 | BQ7: =(BE8-7)*3 -> 69
J8: FT/SEC | K8: =($K$9*4)/K7 -> 20 | L8: BETWEEN | M8: =($K$9*4)/M7 -> 21.818182 | N8: =($K$9*4)/N7 -> 21.818182 | O8: =($K$9*4)/O7 -> 22.857143 | P8: =($K$9*4)/P7 -> 24 | Q8: =($K$9*4)/Q7 -> 25.263158 | AD8: FT/SEC | AE8: =($AE$9*4)/AE7 -> 21.176471 | AF8: BETWEEN | AG8: =($AE$9*4)/AG7 -> 24 | AH8: =($AE$9*4)/AH7 -> 24 | AI8: =($AE$9*4)/AI7 -> 24.827586 | AJ8: =($AE$9*4)/AJ7 -> 26.181818 | AK8: =($AE$9*4)/AK7 -> 27.692308 | AX8: FT/SEC | AY8: =($AY$9*4)/AY7 -> 22.5 | AZ8: BETWEEN | BA8: =($AY$9*4)/BA7 -> 24.827586 | BB8: =($AY$9*4)/BB7 -> 24.827586 | BC8: =($AY$9*4)/BC7 -> 25.714286 | BD8: =($AY$9*4)/BD7 -> 27.692308 | BE8: =($AY$9*4)/BE7 -> 30
J9: Base Length | K9: 90 | AD9: Base Length | AE9: 90 | AX9: Base Length | AY9: 90
B10: Speed Medal Requirements | D10: SPEEDSCORE | N10: Must Meet all Thresholds in the category | T10: =SUM(T7,T5) -> 78 | V10: =SUM(V7,V5) -> 88.514786 | W10: =SUM(W7,W5) -> 125 | AA10: =SUM(AA7,AA5) -> 93.238095 | AB10: =SUM(AB7,AB5) -> 99.230769 | AC10: =SUM(AC7,AC5) -> 105.78947 | AH10: Must Meet all Thresholds in the category | AN10: =SUM(AN7,AN5) -> 84.909693 | AP10: =SUM(AP7,AP5) -> 98.35443 | AQ10: =SUM(AQ7,AQ5) -> 125 | AU10: =SUM(AU7,AU5) -> 102.61263 | AV10: =SUM(AV7,AV5) -> 108.54545 | AW10: =SUM(AW7,AW5) -> 117.13326 | BB10: Must Meet all Thresholds in the category | BH10: =SUM(BH7,BH5) -> 97.308511 | BJ10: =SUM(BJ7,BJ5) -> 108.5391 | BK10: =SUM(BK7,BK5) -> 145 | BO10: =SUM(BO7,BO5) -> 112.28571 | BP10: =SUM(BP7,BP5) -> 120.48869 | BQ10: =SUM(BQ7,BQ5) -> 133.71429
B11: Strength | C11: Push Ups | D11: APUSH60 | E11: Record the number of push ups the player can do in 60 seconds | F11: INPUT with 60 second countdown Timer | H11: Number | I11: 0 - 60 | K11: 24 | L11: BETWEEN | M11: 35 | N11: 35 | O11: 38 | P11: 41 | Q11: 44 | R11: APUSH60/2 | S11: =K11 -> 24 | T11: =S11/2 -> 12 | U11: =M11 -> 35 | V11: =U11/2 -> 17.5 | W11: 25 | AA11: =O11/2 -> 19 | AB11: =P11/2 -> 20.5 | AC11: =Q11/2 -> 22 | AE11: 26 | AF11: BETWEEN | AG11: 38 | AH11: 38 | AI11: 40 | AJ11: 44 | AK11: 48 | AL11: APUSH60/2 | AM11: =AE11 -> 26 | AN11: =AM11/2 -> 13 | AO11: =AG11 -> 38 | AP11: =AO11/2 -> 19 | AQ11: 25 | AU11: =AI11/2 -> 20 | AV11: =AJ11/2 -> 22 | AW11: =AK11/2 -> 24 | AY11: 28 | AZ11: BETWEEN | BA11: 40 | BB11: 40 | BC11: 44 | BD11: 47 | BE11: 50 | BF11: APUSH60/2 | BG11: =AY11 -> 28 | BH11: =BG11/2 -> 14 | BI11: =BA11 -> 40 | BJ11: =BI11/2 -> 20 | BK11: 25 | BO11: =BC11/2 -> 22 | BP11: =BD11/2 -> 23.5 | BQ11: =BE11/2 -> 25
C12: Sit Ups | D12: ASIT60 | E12: Record the number of sit-ups the player can do in 60 seconds | F12: INPUT with 60 second countdown Timer | H12: Number | I12: 0 - 60 | K12: 30 | L12: BETWEEN | M12: 40 | N12: 40 | O12: 43 | P12: 46 | Q12: 50 | R12: ASIT60/3 | S12: =K12 -> 30 | T12: =S12/3 -> 10 | U12: =M12 -> 40 | V12: =U12/3 -> 13.333333 | W12: 25 | AA12: =O12/3 -> 14.333333 | AB12: =P12/3 -> 15.333333 | AC12: =Q12/3 -> 16.666667 | AE12: 33 | AF12: BETWEEN | AG12: 42 | AH12: 42 | AI12: 45 | AJ12: 48 | AK12: 52 | AL12: ASIT60/3 | AM12: =AE12 -> 33 | AN12: =AM12/3 -> 11 | AO12: =AG12 -> 42 | AP12: =AO12/3 -> 14 | AQ12: 25 | AU12: =AI12/3 -> 15 | AV12: =AJ12/3 -> 16 | AW12: =AK12/3 -> 17.333333 | AY12: 35 | AZ12: BETWEEN | BA12: 45 | BB12: 45 | BC12: 48 | BD12: 51 | BE12: 55 | BF12: ASIT60/3 | BG12: =AY12 -> 35 | BH12: =BG12/3 -> 11.666667 | BI12: =BA12 -> 45 | BJ12: =BI12/3 -> 15 | BK12: 25 | BO12: =BC12/3 -> 16 | BP12: =BD12/3 -> 17 | BQ12: =BE12/3 -> 18.333333
C13: Pull Ups | D13: APULL60 | E13: Record the number of pull-ups the player can do in 60 seconds | F13: INPUT with 60 second countdown Timer | H13: Number | I13: 0 - 60 | K13: 6 | L13: BETWEEN | M13: 12 | N13: 12 | O13: 15 | P13: 18 | Q13: 20 | R13: APUSH60 | S13: =K13 -> 6 | T13: =S13 -> 6 | U13: =M13 -> 12 | V13: =U13 -> 12 | W13: 25 | AA13: =O13 -> 15 | AB13: =P13 -> 18 | AC13: =Q13 -> 20 | AE13: 8 | AF13: BETWEEN | AG13: 14 | AH13: 14 | AI13: 17 | AJ13: 20 | AK13: 22 | AL13: APUSH60 | AM13: =AE13 -> 8 | AN13: =AM13 -> 8 | AO13: =AG13 -> 14 | AP13: =AO13 -> 14 | AQ13: 25 | AU13: =AI13 -> 17 | AV13: =AJ13 -> 20 | AW13: =AK13 -> 22 | AY13: 10 | AZ13: BETWEEN | BA13: 16 | BB13: 16 | BC13: 18 | BD13: 21 | BE13: 25 | BF13: APUSH60 | BG13: =AY13 -> 10 | BH13: =BG13 -> 10 | BI13: =BA13 -> 16 | BJ13: =BI13 -> 16 | BK13: 25 | BO13: =BC13 -> 18 | BP13: =BD13 -> 21 | BQ13: =BE13 -> 25
B14: Strength Medal Requirments | D14: STRENGTHSCORE | N14: Must Meet all Thresholds in the category | T14: =SUM(T11:T13) -> 28 | V14: =SUM(V11:V13) -> 42.833333 | W14: =SUM(W11:W13) -> 75 | AA14: =SUM(AA11:AA13) -> 48.333333 | AB14: =SUM(AB11:AB13) -> 53.833333 | AC14: =SUM(AC11:AC13) -> 58.666667 | AH14: Must Meet all Thresholds in the category | AN14: =SUM(AN11:AN13) -> 32 | AP14: =SUM(AP11:AP13) -> 47 | AQ14: =SUM(AQ11:AQ13) -> 75 | AU14: =SUM(AU11:AU13) -> 52 | AV14: =SUM(AV11:AV13) -> 58 | AW14: =SUM(AW11:AW13) -> 63.333333 | BB14: Must Meet all Thresholds in the category | BH14: =SUM(BH11:BH13) -> 35.666667 | BJ14: =SUM(BJ11:BJ13) -> 51 | BK14: =SUM(BK11:BK13) -> 75 | BO14: =SUM(BO11:BO13) -> 56 | BP14: =SUM(BP11:BP13) -> 61.5 | BQ14: =SUM(BQ11:BQ13) -> 68.333333
B15: Power | C15: Vertical Jump | D15: ASPJUMP | E15: Measure the player's max vertical jump. The player can squat slightly to start, but cannot take a running start.The player gets 3 attempts | F15: INPUT | G15: Separate Entry for each of the 3 attempts | H15: Inches to the .25 of an inch | I15: 4 inches - 50 inches | K15: 13 | L15: BETWEEN | M15: 18 | N15: 18 | O15: 19 | P15: 20 | Q15: 22 | R15: =$D15 -> ASPJUMP | S15: =K15 -> 13 | T15: =S15 -> 13 | U15: =M15 -> 18 | V15: =U15 -> 18 | W15: 30 | AA15: =O15 -> 19 | AB15: =P15 -> 20 | AC15: =Q15 -> 22 | AE15: 14 | AF15: BETWEEN | AG15: 20 | AH15: 20 | AI15: 22 | AJ15: 24 | AK15: 26 | AL15: =$D15 -> ASPJUMP | AM15: =AE15 -> 14 | AN15: =AM15 -> 14 | AO15: =AG15 -> 20 | AP15: =AO15 -> 20 | AQ15: 30 | AU15: =AI15 -> 22 | AV15: =AJ15 -> 24 | AW15: =AK15 -> 26 | AY15: 18 | AZ15: BETWEEN | BA15: 24 | BB15: 24 | BC15: 26 | BD15: 28 | BE15: 30 | BF15: =$D15 -> ASPJUMP | BG15: =AY15 -> 18 | BH15: =BG15 -> 18 | BI15: =BA15 -> 24 | BJ15: =BI15 -> 24 | BK15: 35 | BO15: =BC15 -> 26 | BP15: =BD15 -> 28 | BQ15: =BE15 -> 30
B16: Power | C16: Seated Chest Pass | D16: ASPSCP | E16: Have the player sit on the edge of a chair or bench and hold a medicine ball with both hands against their chest. Have the player throw the medicine ball forward as far as possible. The player gets 3 attempts | F16: INPUT | G16: Separate Entry for each of the 3 attempts | H16: Feet and Inches | I16: 2ft - 40 ft | K16: 10 | L16: BETWEEN | M16: 14 | N16: 14 | O16: 15 | P16: 17 | Q16: 19 | R16: =$D16 -> ASPSCP | S16: =K16 -> 10 | T16: =S16 -> 10 | U16: =M16 -> 14 | V16: =U16 -> 14 | W16: 30 | AA16: =O16 -> 15 | AB16: =P16 -> 17 | AC16: =Q16 -> 19 | AE16: 12 | AF16: BETWEEN | AG16: 18 | AH16: 18 | AI16: 19 | AJ16: 20 | AK16: 22 | AL16: =$D16 -> ASPSCP | AM16: =AE16 -> 12 | AN16: =AM16 -> 12 | AO16: =AG16 -> 18 | AP16: =AO16 -> 18 | AQ16: 30 | AU16: =AI16 -> 19 | AV16: =AJ16 -> 20 | AW16: =AK16 -> 22 | AY16: 16 | AZ16: BETWEEN | BA16: 22 | BB16: 22 | BC16: 24 | BD16: 26 | BE16: 28 | BF16: =$D16 -> ASPSCP | BG16: =AY16 -> 16 | BH16: =BG16 -> 16 | BI16: =BA16 -> 22 | BJ16: =BI16 -> 22 | BK16: 35 | BO16: =BC16 -> 24 | BP16: =BD16 -> 26 | BQ16: =BE16 -> 28
C17: Sit up and throw | D17: ASPSUP | E17: Have the player start in a hook-line position with a medicine ball above their head. Have the player site up and throw the medicine ball as far as possible.The player gets 3 attempts | F17: INPUT | G17: Separate Entry for each of the 3 attempts | H17: Feet and Inches | I17: 2ft - 40 ft | K17: 10 | L17: BETWEEN | M17: 14 | N17: 14 | O17: 15 | P17: 17 | Q17: 19 | R17: =$D17 -> ASPSUP | S17: =K17 -> 10 | T17: =S17 -> 10 | U17: =M17 -> 14 | V17: =U17 -> 14 | W17: 30 | AA17: =O17 -> 15 | AB17: =P17 -> 17 | AC17: =Q17 -> 19 | AE17: 12 | AF17: BETWEEN | AG17: 18 | AH17: 18 | AI17: 19 | AJ17: 20 | AK17: 22 | AL17: =$D17 -> ASPSUP | AM17: =AE17 -> 12 | AN17: =AM17 -> 12 | AO17: =AG17 -> 18 | AP17: =AO17 -> 18 | AQ17: 30 | AU17: =AI17 -> 19 | AV17: =AJ17 -> 20 | AW17: =AK17 -> 22 | AY17: 16 | AZ17: BETWEEN | BA17: 22 | BB17: 22 | BC17: 24 | BD17: 26 | BE17: 28 | BF17: =$D17 -> ASPSUP | BG17: =AY17 -> 16 | BH17: =BG17 -> 16 | BI17: =BA17 -> 22 | BJ17: =BI17 -> 22 | BK17: 35 | BO17: =BC17 -> 24 | BP17: =BD17 -> 26 | BQ17: =BE17 -> 28
B18: Power Medal Requirements | D18: POWERSCORE | N18: Must Meet all Thresholds in the category | T18: =SUM(T15:T17) -> 33 | V18: =SUM(V15:V17) -> 46 | W18: =SUM(W15:W17) -> 90 | AA18: =SUM(AA15:AA17) -> 49 | AB18: =SUM(AB15:AB17) -> 54 | AC18: =SUM(AC15:AC17) -> 60 | AH18: Must Meet all Thresholds in the category | AN18: =SUM(AN15:AN17) -> 38 | AP18: =SUM(AP15:AP17) -> 56 | AQ18: =SUM(AQ15:AQ17) -> 90 | AU18: =SUM(AU15:AU17) -> 60 | AV18: =SUM(AV15:AV17) -> 64 | AW18: =SUM(AW15:AW17) -> 70 | BB18: Must Meet all Thresholds in the category | BH18: =SUM(BH15:BH17) -> 50 | BJ18: =SUM(BJ15:BJ17) -> 68 | BK18: =SUM(BK15:BK17) -> 105 | BO18: =SUM(BO15:BO17) -> 74 | BP18: =SUM(BP15:BP17) -> 80 | BQ18: =SUM(BQ15:BQ17) -> 86
B19: Balance | C19: SLS Eyes Open | D19: BSLEO | E19: Have the player get into a single leg stance with their thigh parallel to the ground and the arms by their side. Once stable, have them hold this position for as long as possible up to 30 seconds. | F19: INPUT with Stopwatch that automatically stops at 30 seconds. The user can click a stop button to record the time. | G19: Separate Entry for Right and Left Side | H19: Time - Seconds to the hundreth | I19: 0 Seconds - 30 Seconds | K19: 15 | L19: BETWEEN | M19: 24 | N19: 24 | O19: 25 | P19: 27 | Q19: 30 | R19: BSLEO/3 | S19: =K19 -> 15 | T19: =S19/3 -> 5 | U19: =M19 -> 24 | V19: =U19/3 -> 8 | W19: =30/3 -> 10 | AA19: =O19/3 -> 8.3333333 | AB19: =P19/3 -> 9 | AC19: =Q19/3 -> 10 | AE19: 15 | AF19: BETWEEN | AG19: 24 | AH19: 24 | AI19: 25 | AJ19: 27 | AK19: 30 | AL19: BSLEO/3 | AM19: =AE19 -> 15 | AN19: =AM19/3 -> 5 | AO19: =AG19 -> 24 | AP19: =AO19/3 -> 8 | AQ19: =30/3 -> 10 | AU19: =AI19/3 -> 8.3333333 | AV19: =AJ19/3 -> 9 | AW19: =AK19/3 -> 10 | AY19: 15 | AZ19: BETWEEN | BA19: 24 | BB19: 24 | BC19: 25 | BD19: 27 | BE19: 30 | BF19: BSLEO/3 | BG19: =AY19 -> 15 | BH19: =BG19/3 -> 5 | BI19: =BA19 -> 24 | BJ19: =BI19/3 -> 8 | BK19: =30/3 -> 10 | BO19: =BC19/3 -> 8.3333333 | BP19: =BD19/3 -> 9 | BQ19: =BE19/3 -> 10
C20: SLS Eyes Closed | D20: BSLEC | E20: Have the player get into a single leg stance with their thigh parallel to the ground and the arms by their side. Once stable, have the player close their eyes and hold this position for as long as possible up to 30 seconds. | F20: INPUT with Stopwatch that automatically stops at 30 seconds. The user can click a stop button to record the time. | G20: Separate Entry for Right and Left Side | H20: Time - Seconds to the hundreth | I20: 0 Seconds - 30 Seconds | K20: 15 | L20: BETWEEN | M20: 21.5 | N20: 21.5 | O20: 23 | P20: 25 | Q20: 27 | R20: BSLEC/2 | S20: =K20 -> 15 | T20: =S20/2 -> 7.5 | U20: =M20 -> 21.5 | V20: =U20/2 -> 10.75 | W20: =30/2 -> 15 | AA20: =O20/2 -> 11.5 | AB20: =P20/2 -> 12.5 | AC20: =Q20/2 -> 13.5 | AE20: 15 | AF20: BETWEEN | AG20: 21.5 | AH20: 21.5 | AI20: 23 | AJ20: 25 | AK20: 27 | AL20: BSLEC/2 | AM20: =AE20 -> 15 | AN20: =AM20/2 -> 7.5 | AO20: =AG20 -> 21.5 | AP20: =AO20/2 -> 10.75 | AQ20: =30/2 -> 15 | AU20: =AI20/2 -> 11.5 | AV20: =AJ20/2 -> 12.5 | AW20: =AK20/2 -> 13.5 | AY20: 15 | AZ20: BETWEEN | BA20: 21.5 | BB20: 21.5 | BC20: 23 | BD20: 25 | BE20: 27 | BF20: BSLEC/2 | BG20: =AY20 -> 15 | BH20: =BG20/2 -> 7.5 | BI20: =BA20 -> 21.5 | BJ20: =BI20/2 -> 10.75 | BK20: =30/2 -> 15 | BO20: =BC20/2 -> 11.5 | BP20: =BD20/2 -> 12.5 | BQ20: =BE20/2 -> 13.5
B21: Balance Medal Requirements | D21: BALANCESCORE | N21: Must Meet all Thresholds in the category | T21: =SUM(T19:T20) -> 12.5 | V21: =SUM(V19:V20) -> 18.75 | W21: =SUM(W19:W20) -> 25 | AA21: =SUM(AA19:AA20) -> 19.833333 | AB21: =SUM(AB19:AB20) -> 21.5 | AC21: =SUM(AC19:AC20) -> 23.5 | AH21: Must Meet all Thresholds in the category | AN21: =SUM(AN19:AN20) -> 12.5 | AP21: =SUM(AP19:AP20) -> 18.75 | AQ21: =SUM(AQ19:AQ20) -> 25 | AU21: =SUM(AU19:AU20) -> 19.833333 | AV21: =SUM(AV19:AV20) -> 21.5 | AW21: =SUM(AW19:AW20) -> 23.5 | BB21: Must Meet all Thresholds in the category | BH21: =SUM(BH19:BH20) -> 12.5 | BJ21: =SUM(BJ19:BJ20) -> 18.75 | BK21: =SUM(BK19:BK20) -> 25 | BO21: =SUM(BO19:BO20) -> 19.833333 | BP21: =SUM(BP19:BP20) -> 21.5 | BQ21: =SUM(BQ19:BQ20) -> 23.5
B22: Mobility | C22: MSR | D22: MSR | E22: Have the player stand straight, feet together, with a bat across the shoulders. Then have them rotate their body around to look behind. The player should be able to rotate their torso more than 180 degrees. | F22: SELECT - Less than 180 Degrees, Equal to 180 Degrees, Greater than 180 Degress | G22: Separate Selection for Right and Left Side | H22: Select only 1 option | I22: No Range - Specific Options | K22: Less than 180 Degrees Both Sides | L22: This could be any combinantion between the low and high options | M22: Greater than 180 Degrees Both Sides | N22: N/A | O22: N/A | P22: N/A | Q22: Greater than 180 Degrees Both Sides | R22: Greater Than 180 Degrees=3, Equal to 180 Degrees=1, Less than 180 Degrees=0 Add total for right and left side | S22: =K22 -> Less than 180 Degrees Both Sides | T22: 0 | U22: =L22 -> This could be any combinantion between the low and high options | V22: 4 | W22: 6 | AA22: 6 | AB22: 6 | AC22: 6 | AE22: Less than 180 Degrees Both Sides | AF22: This could be any combinantion between the low and high options | AG22: Greater than 180 Degrees Both Sides | AH22: N/A | AI22: N/A | AJ22: N/A | AK22: Greater than 180 Degrees Both Sides | AL22: Greater Than 180 Degrees=3, Equal to 180 Degrees=1, Less than 180 Degrees=0 Add total for right and left side | AM22: =AE22 -> Less than 180 Degrees Both Sides | AN22: 0 | AO22: =AF22 -> This could be any combinantion between the low and high options | AP22: 4 | AQ22: 6 | AU22: 6 | AV22: 6 | AW22: 6 | AY22: Less than 180 Degrees Both Sides | AZ22: This could be any combinantion between the low and high options | BA22: Greater than 180 Degrees Both Sides | BB22: N/A | BC22: N/A | BD22: N/A | BE22: Greater than 180 Degrees Both Sides | BF22: Greater Than 180 Degrees=3, Equal to 180 Degrees=1, Less than 180 Degrees=0 Add total for right and left side | BG22: =AY22 -> Less than 180 Degrees Both Sides | BH22: 0 | BI22: =AZ22 -> This could be any combinantion between the low and high options | BJ22: 4 | BK22: 6 | BO22: 6 | BP22: 6 | BQ22: 6
C23: Toe Touch | D23: MTT | E23: Have the player stand tall with hte feet together. Have them try to touch their toes without bending the knees. If they can touch their toes, have them try to touch the ground in front of their toes. | F23: SELECT - Cannot Touch Toes, Touches Toes, Touches Ground | H23: Select only 1 option | I23: No Range - Specific Options | K23: Cannot Touch Toes | L23: Touches Toes | M23: Touches Ground | N23: N/A | O23: Touches Toes | P23: N/A | Q23: Touches Ground | R23: Cannot Touch toes=0, Touches Toes=3, Touches Ground=6 | S23: =K23 -> Cannot Touch Toes | T23: 0 | U23: =L23 -> Touches Toes | V23: 3 | W23: 6 | AA23: 6 | AB23: 6 | AC23: 6 | AE23: Cannot Touch Toes | AF23: Touches Toes | AG23: Touches Ground | AH23: N/A | AI23: Touches Toes | AJ23: N/A | AK23: Touches Ground | AL23: Cannot Touch toes=0, Touches Toes=3, Touches Ground=6 | AM23: =AE23 -> Cannot Touch Toes | AN23: 0 | AO23: =AF23 -> Touches Toes | AP23: 3 | AQ23: 6 | AU23: 6 | AV23: 6 | AW23: 6 | AY23: Cannot Touch Toes | AZ23: Touches Toes | BA23: Touches Ground | BB23: N/A | BC23: Touches Toes | BD23: N/A | BE23: Touches Ground | BF23: Cannot Touch toes=0, Touches Toes=3, Touches Ground=6 | BG23: =AY23 -> Cannot Touch Toes | BH23: 0 | BI23: =AZ23 -> Touches Toes | BJ23: 3 | BK23: 6 | BO23: 6 | BP23: 6 | BQ23: 6
C24: Deep Squat | D24: MDS | E24: Have the player stand with their feet shoulder width apart with the arms striaght above their head. Have them do a deep squat trying to get their pelvis below the knees without the arms moving forward or the ankles flaring. | F24: SELECT - Full Overhead Deep Squat, Arms Move Forward, Pelvis not below the knees, Ankles Flare | G24: Full Overhead Deep Squat, Arms move forward of head, Pelvis not below the hips, Ankles Flare | H24: Select 1 or Multiple Options - If "Full Overhead Deep Squat" is selected, then the other options become unavailable. If not, then the user could select one or more of the remaining options. | I24: No Range - Specific Options | K24: 2 or more of Arms move forward of head, Pelvis not below the hips, Ankles Flare | L24: 1 or less of Arms move forward of head, Pelvis not below the hips, Ankles Flare | M24: Full Overhead Deep Squat | N24: N/A | O24: N/A | P24: N/A | Q24: Full Overhead Deep Squat | R24: Full Overhead Deep Squat=9, For each selection other than Full Overhead Deep Squat, minus 3 points. 1 Selection= 6, 2 Selections=3, 3 Selections=0 | S24: =K24 -> 2 or more of Arms move forward of head, Pelvis not below the hips, Ankles Flare | T24: 3 | U24: =L24 -> 1 or less of Arms move forward of head, Pelvis not below the hips, Ankles Flare | V24: 3 | W24: 9 | AA24: 9 | AB24: 9 | AC24: 9 | AE24: 2 or more of Arms move forward of head, Pelvis not below the hips, Ankles Flare | AF24: 1 or less of Arms move forward of head, Pelvis not below the hips, Ankles Flare | AG24: Full Overhead Deep Squat | AH24: N/A | AI24: N/A | AJ24: N/A | AK24: Full Overhead Deep Squat | AL24: Full Overhead Deep Squat=9, For each selection other than Full Overhead Deep Squat, minus 3 points. 1 Selection= 6, 2 Selections=3, 3 Selections=0 | AM24: =AE24 -> 2 or more of Arms move forward of head, Pelvis not below the hips, Ankles Flare | AN24: 3 | AO24: =AF24 -> 1 or less of Arms move forward of head, Pelvis not below the hips, Ankles Flare | AP24: 3 | AQ24: 9 | AU24: 9 | AV24: 9 | AW24: 9 | AY24: 2 or more of Arms move forward of head, Pelvis not below the hips, Ankles Flare | AZ24: 1 or less of Arms move forward of head, Pelvis not below the hips, Ankles Flare | BA24: Full Overhead Deep Squat | BB24: N/A | BC24: N/A | BD24: N/A | BE24: Full Overhead Deep Squat | BF24: Full Overhead Deep Squat=9, For each selection other than Full Overhead Deep Squat, minus 3 points. 1 Selection= 6, 2 Selections=3, 3 Selections=0 | BG24: =AY24 -> 2 or more of Arms move forward of head, Pelvis not below the hips, Ankles Flare | BH24: 3 | BI24: =AZ24 -> 1 or less of Arms move forward of head, Pelvis not below the hips, Ankles Flare | BJ24: 3 | BK24: 9 | BO24: 9 | BP24: 9 | BQ24: 9
B25: Mobility Medal Requirements | D25: MOBILITYSCORE | N25: If One Test meets Platium threshold | O25: If One Test meets Platium threshold and Toe Touch meets Silver threshold | P25: If two tests meet platium threshold | Q25: If all three tests meet platinum threshold | T25: =SUM(T22:T24) -> 3 | V25: =SUM(V22:V24) -> 10 | W25: =SUM(W22:W24) -> 21 | AA25: =SUM(AA22:AA24) -> 21 | AB25: =SUM(AB22:AB24) -> 21 | AC25: =SUM(AC22:AC24) -> 21 | AH25: If One Test meets Platium threshold | AI25: If One Test meets Platium threshold and Toe Touch meets Silver threshold | AJ25: If two tests meet platium threshold | AK25: If all three tests meet platinum threshold | AN25: =SUM(AN22:AN24) -> 3 | AP25: =SUM(AP22:AP24) -> 10 | AQ25: =SUM(AQ22:AQ24) -> 21 | AU25: =SUM(AU22:AU24) -> 21 | AV25: =SUM(AV22:AV24) -> 21 | AW25: =SUM(AW22:AW24) -> 21 | BB25: If One Test meets Platium threshold | BC25: If One Test meets Platium threshold and Toe Touch meets Silver threshold | BD25: If two tests meet platium threshold | BE25: If all three tests meet platinum threshold | BH25: =SUM(BH22:BH24) -> 3 | BJ25: =SUM(BJ22:BJ24) -> 10 | BK25: =SUM(BK22:BK24) -> 21 | BO25: =SUM(BO22:BO24) -> 21 | BP25: =SUM(BP22:BP24) -> 21 | BQ25: =SUM(BQ22:BQ24) -> 21
